<?xml version="1.0" encoding="utf-8"?>
<!-- =================================================================================== -->
<!-- |    This document was autogenerated by xacro from ../robots/athos_description.xacro | -->
<!-- |    EDITING THIS FILE BY HAND IS NOT RECOMMENDED                                 | -->
<!-- =================================================================================== -->
<robot name="athos_description" xmlns:controller="http://playerstage.sourceforge.net/gazebo/xmlschema/#controller" xmlns:interface="http://playerstage.sourceforge.net/gazebo/xmlschema/#interface" xmlns:sensor="http://playerstage.sourceforge.net/gazebo/xmlschema/#sensor" xmlns:xacro="http://ros.org/wiki/xacro">
  <!-- Chassis -->
  <link name="base_link">
    <inertial>
      <mass value="10.0"/>
      <origin xyz="0 0 0.177"/>
      <inertia ixx="0.3338" ixy="0.0" ixz="0.0" iyy="0.4783" iyz="0.0" izz="0.3338"/>
    </inertial>
    <visual>
      <origin rpy="0 0 0" xyz="0 0 0.177"/>
      <geometry name="pioneer_geom">
        <mesh filename="package://athos_description/meshes/chassis.stl"/>
      </geometry>
      <material name="ChassisRed"/>
    </visual>
    <collision>
      <origin rpy="0 0 0" xyz="0 0 0.177"/>
      <geometry>
        <mesh filename="package://athos_description/meshes/chassis.stl"/>
      </geometry>
    </collision>
  </link>
  <gazebo reference="base_link">
    <material value="Gazebo/Red"/>
  </gazebo>
  <!-- Top -->
  <link name="top_plate">
    <inertial>
      <mass value="0.1"/>
      <origin xyz="-0.025 0 -0.223"/>
      <inertia ixx="1.0" ixy="0.0" ixz="0.0" iyy="1.0" iyz="0.0" izz="1.0"/>
    </inertial>
    <visual>
      <origin rpy="0 0 0" xyz="0 0 0"/>
      <geometry name="pioneer_geom">
        <mesh filename="package://athos_description/meshes/top.stl"/>
      </geometry>
      <material name="TopBlack">
        <color rgba="0.038 0.038 0.038 1.0"/>
      </material>
    </visual>
    <collision>
      <origin rpy="0 0 0" xyz="0 0 0"/>
      <geometry>
        <box size="0 0 0"/>
      </geometry>
    </collision>
  </link>
  <gazebo reference="top_plate">
    <material value="Gazebo/Black"/>
  </gazebo>
  <joint name="base_top_joint" type="fixed">
    <origin rpy="0 0 0" xyz="0.003 0 0.274"/>
    <parent link="base_link"/>
    <child link="top_plate"/>
  </joint>
  <!-- Front + Back Sonar -->
  <link name="front_sonar">
    <inertial>
      <mass value="0.1"/>
      <origin xyz="0 0 0"/>
      <inertia ixx="1.0" ixy="0.0" ixz="0.0" iyy="1.0" iyz="0.0" izz="1.0"/>
    </inertial>
    <visual name="front_sonar_visual">
      <origin rpy="0 0 0" xyz="0 0 0"/>
      <geometry name="pioneer_geom">
        <mesh filename="package://athos_description/meshes/front_sonar.stl"/>
      </geometry>
      <material name="SonarYellow">
        <color rgba="0.715 0.583 0.210 1.0"/>
      </material>
    </visual>
    <collision>
      <origin rpy="0 0 0" xyz="0 0 0"/>
      <geometry>
        <box size="0 0 0"/>
      </geometry>
    </collision>
  </link>
  <gazebo reference="front_sonar">
    <material value="Gazebo/Yellow"/>
  </gazebo>
  <joint name="base_front_joint" type="fixed">
    <origin rpy="0 0 0" xyz="0.193 0 0.25"/>
    <parent link="base_link"/>
    <child link="front_sonar"/>
  </joint>
  <link name="back_sonar">
    <inertial>
      <mass value="0.1"/>
      <origin xyz="0 0 0"/>
      <inertia ixx="1.0" ixy="0.0" ixz="0.0" iyy="1.0" iyz="0.0" izz="1.0"/>
    </inertial>
    <visual name="back_sonar_visual">
      <origin rpy="0 0 0" xyz="0 0 0"/>
      <geometry name="pioneer_geom">
        <mesh filename="package://athos_description/meshes/back_sonar.stl"/>
      </geometry>
      <material name="SonarYellow">
        <color rgba="0.715 0.583 0.210 1.0"/>
      </material>
    </visual>
    <collision>
      <origin rpy="0 0 0" xyz="0 0 0"/>
      <geometry>
        <box size="0 0 0"/>
      </geometry>
    </collision>
  </link>
  <gazebo reference="back_sonar">
    <material value="Gazebo/Yellow"/>
  </gazebo>
  <joint name="base_back_joint" type="fixed">
    <origin rpy="0 0 0" xyz="-0.187 0 0.247"/>
    <parent link="base_link"/>
    <child link="back_sonar"/>
  </joint>
  <!-- <xacro:include filename="$(find cyton_description)/robots/cyton_gazebo_description.urdf"/> -->
  <link name="suporte_base">
    <inertial>
      <origin rpy="0 0 0" xyz="0.16 -0.0717771259809899 0.293842379381435"/>
      <mass value="5"/>
      <inertia ixx="0.0517372413967915" ixy="2.32967941812823E-17" ixz="2.27682456221956E-18" iyy="0.0813923285839342" iyz="0.000218090834338814" izz="0.0306997500302406"/>
    </inertial>
    <visual>
      <origin rpy="0 0 0" xyz="0 0 0"/>
      <geometry>
        <mesh filename="package://athos_description/meshes/suporte_base.STL"/>
      </geometry>
      <material name="">
        <color rgba="0.792156862745098 0.819607843137255 0.933333333333333 1"/>
      </material>
    </visual>
    <collision>
      <origin rpy="0 0 0" xyz="0 0 0"/>
      <geometry>
        <mesh filename="package://athos_description/meshes/suporte_base.STL"/>
      </geometry>
    </collision>
  </link>
  <link name="suporte_monitor">
    <inertial>
      <origin rpy="0 0 0" xyz="0.00735106382978723 -0.0176489361702128 -0.16"/>
      <mass value="0.0451200000000001"/>
      <inertia ixx="0.000387649159148937" ixy="-1.54468085106384E-06" ixz="3.87275403044827E-21" iyy="0.000387649159148937" iyz="-6.76739338593385E-22" izz="5.25031829787237E-06"/>
    </inertial>
    <visual>
      <origin rpy="0 0 0" xyz="0 0 0"/>
      <geometry>
        <mesh filename="package://athos_description/meshes/suporte_monitor.STL"/>
      </geometry>
      <material name="">
        <color rgba="0.792156862745098 0.819607843137255 0.933333333333333 1"/>
      </material>
    </visual>
    <collision>
      <origin rpy="0 0 0" xyz="0 0 0"/>
      <geometry>
        <mesh filename="package://athos_description/meshes/suporte_monitor.STL"/>
      </geometry>
    </collision>
  </link>
  <joint name="monitor_joint" type="fixed">
    <origin rpy="-1.5707963267949 -6.12303176911189E-17 -1.5707963267949" xyz="0.32 -0.103 0.335"/>
    <parent link="suporte_base"/>
    <child link="suporte_monitor"/>
    <axis xyz="0 0 0"/>
  </joint>
  <link name="suporte_depth">
    <inertial>
      <origin rpy="0 0 0" xyz="0.13 0.00149999999999995 0.035"/>
      <mass value="0.0546000000000001"/>
      <inertia ixx="2.233595E-05" ixy="2.47051276282504E-22" ixz="-8.00805526497683E-34" iyy="0.000329875" iyz="-8.47032947254312E-23" izz="0.00030762095"/>
    </inertial>
    <visual>
      <origin rpy="0 0 0" xyz="0 0 0"/>
      <geometry>
        <mesh filename="package://athos_description/meshes/suporte_depth.STL"/>
      </geometry>
      <material name="">
        <color rgba="0.792156862745098 0.819607843137255 0.933333333333333 1"/>
      </material>
    </visual>
    <collision>
      <origin rpy="0 0 0" xyz="0 0 0"/>
      <geometry>
        <mesh filename="package://athos_description/meshes/suporte_depth.STL"/>
      </geometry>
    </collision>
  </link>
  <joint name="depth_joint" type="fixed">
    <origin rpy="1.5707963267949 0 0" xyz="0.03 -0.043 0.511"/>
    <parent link="suporte_base"/>
    <child link="suporte_depth"/>
    <axis xyz="0 0 0"/>
  </joint>
  <link name="suporte_kinect">
    <inertial>
      <origin rpy="0 0 0" xyz="0.16 0.0149999999999999 0.03"/>
      <mass value="0.374047006313238"/>
      <inertia ixx="0.000133581294455335" ixy="-1.44622228884143E-20" ixz="-9.19421327041379E-20" iyy="0.0032955828515892" iyz="1.65953110393451E-20" izz="0.00322173401727873"/>
    </inertial>
    <visual>
      <origin rpy="0 0 0" xyz="0 0 0"/>
      <geometry>
        <mesh filename="package://athos_description/meshes/suporte_kinect.STL"/>
      </geometry>
      <material name="">
        <color rgba="0.792156862745098 0.819607843137255 0.933333333333333 1"/>
      </material>
    </visual>
    <collision>
      <origin rpy="0 0 0" xyz="0 0 0"/>
      <geometry>
        <mesh filename="package://athos_description/meshes/suporte_kinect.STL"/>
      </geometry>
    </collision>
  </link>
  <joint name="kinect_joint" type="fixed">
    <origin rpy="1.5707963267949 0 0" xyz="0 -0.0429999999999997 0.6"/>
    <parent link="suporte_base"/>
    <child link="suporte_kinect"/>
    <axis xyz="0 0 0"/>
  </joint>
  <link name="suporte_armControl">
    <inertial>
      <origin rpy="0 0 0" xyz="0.13 0.015 0.03"/>
      <mass value="0.267051450380625"/>
      <inertia ixx="8.86846066165584E-05" ixy="1.7172769498249E-20" ixz="-2.97977476693918E-20" iyy="0.00157152571659327" iyz="1.07423367606254E-20" izz="0.00152593856431166"/>
    </inertial>
    <visual>
      <origin rpy="0 0 0" xyz="0 0 0"/>
      <geometry>
        <mesh filename="package://athos_description/meshes/suporte_armControl.STL"/>
      </geometry>
      <material name="">
        <color rgba="0.792156862745098 0.819607843137255 0.933333333333333 1"/>
      </material>
    </visual>
    <collision>
      <origin rpy="0 0 0" xyz="0 0 0"/>
      <geometry>
        <mesh filename="package://athos_description/meshes/suporte_armControl.STL"/>
      </geometry>
    </collision>
  </link>
  <joint name="armControl" type="fixed">
    <origin rpy="1.5708 0 0" xyz="0.03 -0.043 0.145"/>
    <parent link="suporte_base"/>
    <child link="suporte_armControl"/>
    <axis xyz="0 0 0"/>
  </joint>
  <link name="tampa1">
    <inertial>
      <origin rpy="0 0 0" xyz="0.0149999999999999 -0.0150000000000001 -0.000491941727426247"/>
      <mass value="0.000874663053495623"/>
      <inertia ixx="6.38808008560932E-08" ixy="-5.78363233423954E-24" ixz="9.27480046753304E-24" iyy="6.38808008560915E-08" iyz="3.84652514330873E-23" izz="1.27617401455768E-07"/>
    </inertial>
    <visual>
      <origin rpy="0 0 0" xyz="0 0 0"/>
      <geometry>
        <mesh filename="package://athos_description/meshes/tampa1.STL"/>
      </geometry>
      <material name="">
        <color rgba="0 0 0"/>
      </material>
    </visual>
    <collision>
      <origin rpy="0 0 0" xyz="0 0 0"/>
      <geometry>
        <mesh filename="package://athos_description/meshes/tampa1.STL"/>
      </geometry>
    </collision>
  </link>
  <joint name="tampa_joint1" type="fixed">
    <origin rpy="-1.5708 2.0204E-15 -1.5708" xyz="0 -0.043 0.6"/>
    <parent link="suporte_base"/>
    <child link="tampa1"/>
    <axis xyz="0 0 0"/>
  </joint>
  <link name="tampa2">
    <inertial>
      <origin rpy="0 0 0" xyz="0.015 -0.015 -0.000491941727426291"/>
      <mass value="0.000874663053495619"/>
      <inertia ixx="6.38808008560923E-08" ixy="-2.52580935900029E-24" ixz="-3.82450269523941E-24" iyy="6.38808008560915E-08" iyz="-6.23648863168872E-23" izz="1.27617401455767E-07"/>
    </inertial>
    <visual>
      <origin rpy="0 0 0" xyz="0 0 0"/>
      <geometry>
        <mesh filename="package://athos_description/meshes/tampa2.STL"/>
      </geometry>
      <material name="">
        <color rgba="0 0 0"/>
      </material>
    </visual>
    <collision>
      <origin rpy="0 0 0" xyz="0 0 0"/>
      <geometry>
        <mesh filename="package://athos_description/meshes/tampa2.STL"/>
      </geometry>
    </collision>
  </link>
  <joint name="tampa_joint2" type="fixed">
    <origin rpy="-1.5708 -6.123E-17 -1.5708" xyz="0 -0.073 0.6"/>
    <parent link="suporte_base"/>
    <child link="tampa2"/>
    <axis xyz="0 0 0"/>
  </joint>
  <link name="tampa3">
    <inertial>
      <origin rpy="0 0 0" xyz="0.015 0.0150000000000003 0.000491941727426226"/>
      <mass value="0.000874663053495497"/>
      <inertia ixx="6.38808008560803E-08" ixy="-2.34250421564535E-22" ixz="-5.6721059847382E-24" iyy="6.38808008560819E-08" iyz="-5.91525121084966E-23" izz="1.27617401455745E-07"/>
    </inertial>
    <visual>
      <origin rpy="0 0 0" xyz="0 0 0"/>
      <geometry>
        <mesh filename="package://athos_description/meshes/tampa3.STL"/>
      </geometry>
      <material name="">
        <color rgba="0 0 0"/>
      </material>
    </visual>
    <collision>
      <origin rpy="0 0 0" xyz="0 0 0"/>
      <geometry>
        <mesh filename="package://athos_description/meshes/tampa3.STL"/>
      </geometry>
    </collision>
  </link>
  <joint name="tampa_joint3" type="fixed">
    <origin rpy="1.5708 6.123E-17 1.5708" xyz="0.32 -0.103 0.6"/>
    <parent link="suporte_base"/>
    <child link="tampa3"/>
    <axis xyz="0 0 0"/>
  </joint>
  <link name="tampa4">
    <inertial>
      <origin rpy="0 0 0" xyz="0.015 0.0149999999999997 0.000491941727426282"/>
      <mass value="0.000874663053495488"/>
      <inertia ixx="6.38808008560794E-08" ixy="-7.31233136980388E-23" ixz="5.02909026110651E-23" iyy="6.38808008560811E-08" iyz="-4.10567487783576E-23" izz="1.27617401455743E-07"/>
    </inertial>
    <visual>
      <origin rpy="0 0 0" xyz="0 0 0"/>
      <geometry>
        <mesh filename="package://athos_description/meshes/tampa4.STL"/>
      </geometry>
      <material name="">
        <color rgba="0 0 0"/>
      </material>
    </visual>
    <collision>
      <origin rpy="0 0 0" xyz="0 0 0"/>
      <geometry>
        <mesh filename="package://athos_description/meshes/tampa4.STL"/>
      </geometry>
    </collision>
  </link>
  <joint name="tampa_joint4" type="fixed">
    <origin rpy="1.5707963267949 6.12303176911189E-17 1.5707963267949" xyz="0.32 -0.0729999999999996 0.6"/>
    <parent link="suporte_base"/>
    <child link="tampa4"/>
    <axis xyz="0 0 0"/>
  </joint>
  <gazebo reference="tampa1">
    <material value="Gazebo/Grey"/>
  </gazebo>
  <gazebo reference="tampa2">
    <material value="Gazebo/Grey"/>
  </gazebo>
  <gazebo reference="tampa3">
    <material value="Gazebo/Grey"/>
  </gazebo>
  <gazebo reference="tampa4">
    <material value="Gazebo/Grey"/>
  </gazebo>
  <link name="tv">
    <inertial>
      <origin rpy="0 0 0" xyz="-1.14188936084503E-11 0.00631758902771762 0.0456902661812858"/>
      <mass value="1.04139790550844"/>
      <inertia ixx="0.00221521914456974" ixy="-4.16439279484658E-11" ixz="3.63002570493575E-13" iyy="0.00492777814840569" iyz="-3.11823169868443E-05" izz="0.00695266375583539"/>
    </inertial>
    <visual>
      <origin rpy="0 0 0" xyz="0 0 0"/>
      <geometry>
        <mesh filename="package://athos_description/meshes/tv.STL"/>
      </geometry>
      <material name="">
        <color rgba="0.792156862745098 0.819607843137255 0.933333333333333 1"/>
      </material>
    </visual>
    <collision>
      <origin rpy="0 0 0" xyz="0 0 0"/>
      <geometry>
        <mesh filename="package://athos_description/meshes/tv.STL"/>
      </geometry>
    </collision>
  </link>
  <joint name="suporte2tv" type="fixed">
    <origin rpy="1.5707963267949 0 3.14159265358979" xyz="0.159977341921746 -0.1157202428626 0.36"/>
    <parent link="suporte_base"/>
    <child link="tv"/>
    <axis xyz="0 0 0"/>
  </joint>
  <link name="arm_control_box">
    <inertial>
      <origin rpy="0 0 0" xyz="0.0874604605423992 0.0306742048420322 0.0677387951607025"/>
      <mass value="1.88580869219064"/>
      <inertia ixx="0.00396050112760631" ixy="3.40564468788146E-06" ixz="-2.6138309892175E-06" iyy="0.00771581325906805" iyz="-0.000451232161302695" izz="0.00650786557377839"/>
    </inertial>
    <visual>
      <origin rpy="0 0 0" xyz="0 0 0"/>
      <geometry>
        <mesh filename="package://athos_description/meshes/arm_control_box.STL"/>
      </geometry>
      <material name="">
        <color rgba="0.792156862745098 0.819607843137255 0.933333333333333 1"/>
      </material>
    </visual>
    <collision>
      <origin rpy="0 0 0" xyz="0 0 0"/>
      <geometry>
        <mesh filename="package://athos_description/meshes/arm_control_box.STL"/>
      </geometry>
    </collision>
  </link>
  <joint name="suporte2controlbox" type="fixed">
    <origin rpy="1.5707963267949 0 0" xyz="0.0728041142425171 -0.0429999999999999 0.175"/>
    <parent link="suporte_base"/>
    <child link="arm_control_box"/>
    <axis xyz="0 0 0"/>
  </joint>
  <link name="p3at_front_left_axle">
    <inertial>
      <mass value="0.1"/>
      <origin xyz="0 0 0"/>
      <inertia ixx="1.0" ixy="0.0" ixz="0.0" iyy="1.0" iyz="0.0" izz="1.0"/>
    </inertial>
    <visual>
      <origin rpy="0 0 0" xyz="0 0 0"/>
      <geometry name="pioneer_geom">
        <mesh filename="package://athos_description/meshes/axle.stl"/>
      </geometry>
      <material name="AxleGrey">
        <color rgba="0.5 0.5 0.5 1"/>
      </material>
    </visual>
    <collision>
      <origin rpy="0 0 0" xyz="0 0 0"/>
      <geometry>
        <box size="0 0 0"/>
      </geometry>
    </collision>
  </link>
  <gazebo reference="p3at_front_left_axle">
    <material value="Gazebo/Grey"/>
  </gazebo>
  <joint name="base_front_left_axle_joint" type="fixed">
    <origin rpy="0 0 0" xyz="0.135 0.156 0.111"/>
    <parent link="base_link"/>
    <child link="p3at_front_left_axle"/>
  </joint>
  <link name="p3at_front_left_hub">
    <inertial>
      <mass value="0.1"/>
      <origin xyz="0 0 0"/>
      <inertia ixx="1.0" ixy="0.0" ixz="0.0" iyy="1.0" iyz="0.0" izz="1.0"/>
    </inertial>
    <visual>
      <origin rpy="0 0 0" xyz="0 0 0"/>
      <geometry name="pioneer_geom">
        <mesh filename="package://athos_description/meshes/left_hubcap.stl"/>
      </geometry>
      <material name="HubcapYellow">
        <color rgba="1.0 0.811 0.151 1.0"/>
      </material>
    </visual>
    <collision>
      <origin rpy="0 0 0" xyz="0 0 0"/>
      <geometry>
        <box size="0 0 0"/>
      </geometry>
    </collision>
  </link>
  <gazebo reference="p3at_front_left_hub">
    <material value="Gazebo/Yellow"/>
  </gazebo>
  <joint name="base_front_left_hub_joint" type="fixed">
    <origin rpy="0 0 0" xyz="0 0.041 0"/>
    <parent link="p3at_front_left_axle"/>
    <child link="p3at_front_left_hub"/>
  </joint>
  <link name="p3at_front_left_wheel">
    <inertial>
      <mass value="0.5"/>
      <origin xyz="0 0 0"/>
      <inertia ixx="0.012411765597" ixy="0" ixz="0" iyy="0.015218160428" iyz="0" izz="0.011763977943"/>
    </inertial>
    <visual>
      <origin rpy="0 0 0" xyz="0 0 0"/>
      <geometry name="pioneer_geom">
        <mesh filename="package://athos_description/meshes/wheel.stl"/>
      </geometry>
      <material name="WheelBlack">
        <color rgba="0.117 0.117 0.117 1"/>
      </material>
    </visual>
    <collision>
      <origin rpy="-1.57079635 0 0" xyz="0 0 0"/>
      <geometry>
        <!--mesh filename="package://athos_description/meshes/wheel.stl"/-->
        <cylinder length="0.075" radius="0.111"/>
      </geometry>
    </collision>
  </link>
  <gazebo reference="p3at_front_left_wheel">
    <material value="Gazebo/Black"/>
  </gazebo>
  <joint name="p3at_front_left_wheel_joint" type="continuous">
    <axis xyz="0 1 0"/>
    <anchor xyz="0 0 0"/>
    <limit effort="100" velocity="100"/>
    <joint_properties damping="0.7"/>
    <origin rpy="0 0 0" xyz="0 0 0"/>
    <parent link="p3at_front_left_hub"/>
    <child link="p3at_front_left_wheel"/>
  </joint>
  <link name="p3at_front_right_axle">
    <inertial>
      <mass value="0.1"/>
      <origin xyz="0 0 0"/>
      <inertia ixx="1.0" ixy="0.0" ixz="0.0" iyy="1.0" iyz="0.0" izz="1.0"/>
    </inertial>
    <visual>
      <origin rpy="0 0 0" xyz="0 0 0"/>
      <geometry name="pioneer_geom">
        <mesh filename="package://athos_description/meshes/axle.stl"/>
      </geometry>
      <material name="AxleGrey">
        <color rgba="0.5 0.5 0.5 1"/>
      </material>
    </visual>
    <collision>
      <origin rpy="0 0 0" xyz="0 0 0"/>
      <geometry>
        <box size="0 0 0"/>
      </geometry>
    </collision>
  </link>
  <gazebo reference="p3at_front_right_axle">
    <material value="Gazebo/Grey"/>
  </gazebo>
  <joint name="base_front_right_axle_joint" type="fixed">
    <origin rpy="0 0 0" xyz="0.135 -0.156 0.111"/>
    <parent link="base_link"/>
    <child link="p3at_front_right_axle"/>
  </joint>
  <link name="p3at_front_right_hub">
    <inertial>
      <mass value="0.1"/>
      <origin xyz="0 0 0"/>
      <inertia ixx="1.0" ixy="0.0" ixz="0.0" iyy="1.0" iyz="0.0" izz="1.0"/>
    </inertial>
    <visual>
      <origin rpy="0 0 0" xyz="0 0 0"/>
      <geometry name="pioneer_geom">
        <mesh filename="package://athos_description/meshes/right_hubcap.stl"/>
      </geometry>
      <material name="HubcapYellow">
        <color rgba="1.0 0.811 0.151 1.0"/>
      </material>
    </visual>
    <collision>
      <origin rpy="0 0 0" xyz="0 0 0"/>
      <geometry>
        <box size="0 0 0"/>
      </geometry>
    </collision>
  </link>
  <gazebo reference="p3at_front_right_hub">
    <material value="Gazebo/Yellow"/>
  </gazebo>
  <joint name="base_front_right_hub_joint" type="fixed">
    <origin rpy="0 0 0" xyz="0 -0.041 0"/>
    <parent link="p3at_front_right_axle"/>
    <child link="p3at_front_right_hub"/>
  </joint>
  <link name="p3at_front_right_wheel">
    <inertial>
      <mass value="0.5"/>
      <origin xyz="0 0 0"/>
      <inertia ixx="0.012411765597" ixy="0" ixz="0" iyy="0.015218160428" iyz="0" izz="0.011763977943"/>
    </inertial>
    <visual>
      <origin rpy="0 0 0" xyz="0 0 0"/>
      <geometry name="pioneer_geom">
        <mesh filename="package://athos_description/meshes/wheel.stl"/>
      </geometry>
      <material name="WheelBlack">
        <color rgba="0.117 0.117 0.117 1"/>
      </material>
    </visual>
    <collision>
      <origin rpy="-1.57079635 0 0" xyz="0 0 0"/>
      <geometry>
        <!--mesh filename="package://athos_description/meshes/wheel.stl"/-->
        <cylinder length="0.075" radius="0.111"/>
      </geometry>
    </collision>
  </link>
  <gazebo reference="p3at_front_right_wheel">
    <material value="Gazebo/Black"/>
  </gazebo>
  <joint name="p3at_front_right_wheel_joint" type="continuous">
    <axis xyz="0 1 0"/>
    <anchor xyz="0 0 0"/>
    <limit effort="100" velocity="100"/>
    <joint_properties damping="0.7"/>
    <origin rpy="0 0 0" xyz="0 0 0"/>
    <parent link="p3at_front_right_hub"/>
    <child link="p3at_front_right_wheel"/>
  </joint>
  <link name="p3at_back_left_axle">
    <inertial>
      <mass value="0.1"/>
      <origin xyz="0 0 0"/>
      <inertia ixx="1.0" ixy="0.0" ixz="0.0" iyy="1.0" iyz="0.0" izz="1.0"/>
    </inertial>
    <visual>
      <origin rpy="0 0 0" xyz="0 0 0"/>
      <geometry name="pioneer_geom">
        <mesh filename="package://athos_description/meshes/axle.stl"/>
      </geometry>
      <material name="AxleGrey">
        <color rgba="0.5 0.5 0.5 1"/>
      </material>
    </visual>
    <collision>
      <origin rpy="0 0 0" xyz="0 0 0"/>
      <geometry>
        <mesh filename="package://athos_description/meshes/axle.stl"/>
      </geometry>
    </collision>
  </link>
  <gazebo reference="p3at_back_left_axle">
    <material value="Gazebo/Grey"/>
  </gazebo>
  <joint name="bp3at_back_left_axle_joint" type="fixed">
    <origin rpy="0 0 0" xyz="-0.134 0.156 0.111"/>
    <parent link="base_link"/>
    <child link="p3at_back_left_axle"/>
  </joint>
  <link name="p3at_back_left_hub">
    <inertial>
      <mass value="0.1"/>
      <origin xyz="0 0 0"/>
      <inertia ixx="1.0" ixy="0.0" ixz="0.0" iyy="1.0" iyz="0.0" izz="1.0"/>
    </inertial>
    <visual>
      <origin rpy="0 0 0" xyz="0 0 0"/>
      <geometry name="pioneer_geom">
        <mesh filename="package://athos_description/meshes/left_hubcap.stl"/>
      </geometry>
      <material name="HubcapYellow"/>
    </visual>
    <collision>
      <origin rpy="0 0 0" xyz="0 0 0"/>
      <geometry>
        <mesh filename="package://athos_description/meshes/left_hubcap.stl"/>
      </geometry>
    </collision>
  </link>
  <gazebo reference="p3at_back_left_hub">
    <material value="Gazebo/Yellow"/>
  </gazebo>
  <joint name="p3at_back_left_hub_joint" type="fixed">
    <origin rpy="0 0 0" xyz="-0 0.041 0"/>
    <parent link="p3at_back_left_axle"/>
    <child link="p3at_back_left_hub"/>
  </joint>
  <link name="p3at_back_left_wheel">
    <inertial>
      <mass value="0.5"/>
      <origin xyz="0 0 0"/>
      <inertia ixx="0.012411765597" ixy="0" ixz="0" iyy="0.015218160428" iyz="0" izz="0.011763977943"/>
    </inertial>
    <visual>
      <origin rpy="0 0 0" xyz="0 0 0"/>
      <geometry name="pioneer_geom">
        <mesh filename="package://athos_description/meshes/wheel.stl"/>
      </geometry>
      <material name="WheelBlack"/>
    </visual>
    <collision>
      <origin rpy="-1.57079635 0 0" xyz="0 0 0"/>
      <geometry>
        <!--mesh filename="package://athos_description/meshes/wheel.stl"/-->
        <cylinder length="0.075" radius="0.111"/>
      </geometry>
    </collision>
  </link>
  <gazebo reference="p3at_back_left_wheel">
    <material value="Gazebo/Black"/>
  </gazebo>
  <joint name="p3at_back_left_wheel_joint" type="continuous">
    <axis xyz="0 1 0"/>
    <anchor xyz="0 0 0"/>
    <limit effort="100" velocity="100"/>
    <joint_properties damping="0.7"/>
    <origin rpy="0 0 0" xyz="0 0 0"/>
    <parent link="p3at_back_left_hub"/>
    <child link="p3at_back_left_wheel"/>
  </joint>
  <gazebo reference="p3at_back_left_wheel">
    <kp>1000000.0</kp>
    <!-- kp and kd for rubber -->
    <kd>100.0</kd>
    <mu1>10.0</mu1>
    <mu2>1.0</mu2>
    <fdir1>0 1 0</fdir1>
    <!-- is this correct? -->
    <maxVel>1.0</maxVel>
    <minDepth>0.00</minDepth>
  </gazebo>
  <gazebo reference="p3at_front_left_wheel">
    <kp>1000000.0</kp>
    <!-- kp and kd for rubber -->
    <kd>100.0</kd>
    <mu1>10.0</mu1>
    <mu2>1.0</mu2>
    <fdir1>0 1 0</fdir1>
    <!-- is this correct? -->
    <maxVel>1.0</maxVel>
    <minDepth>0.00</minDepth>
  </gazebo>
  <link name="p3at_back_right_axle">
    <inertial>
      <mass value="0.1"/>
      <origin xyz="0 0 0"/>
      <inertia ixx="1.0" ixy="0.0" ixz="0.0" iyy="1.0" iyz="0.0" izz="1.0"/>
    </inertial>
    <visual>
      <origin rpy="0 0 0" xyz="0 0 0"/>
      <geometry name="pioneer_geom">
        <mesh filename="package://athos_description/meshes/axle.stl"/>
      </geometry>
      <material name="AxleGrey">
        <color rgba="0.5 0.5 0.5 1"/>
      </material>
    </visual>
    <collision>
      <origin rpy="0 0 0" xyz="0 0 0"/>
      <geometry>
        <mesh filename="package://athos_description/meshes/axle.stl"/>
      </geometry>
    </collision>
  </link>
  <gazebo reference="p3at_back_right_axle">
    <material value="Gazebo/Grey"/>
  </gazebo>
  <joint name="bp3at_back_right_axle_joint" type="fixed">
    <origin rpy="0 0 0" xyz="-0.134 -0.156 0.111"/>
    <parent link="base_link"/>
    <child link="p3at_back_right_axle"/>
  </joint>
  <link name="p3at_back_right_hub">
    <inertial>
      <mass value="0.1"/>
      <origin xyz="0 0 0"/>
      <inertia ixx="1.0" ixy="0.0" ixz="0.0" iyy="1.0" iyz="0.0" izz="1.0"/>
    </inertial>
    <visual>
      <origin rpy="0 0 0" xyz="0 0 0"/>
      <geometry name="pioneer_geom">
        <mesh filename="package://athos_description/meshes/right_hubcap.stl"/>
      </geometry>
      <material name="HubcapYellow"/>
    </visual>
    <collision>
      <origin rpy="0 0 0" xyz="0 0 0"/>
      <geometry>
        <mesh filename="package://athos_description/meshes/right_hubcap.stl"/>
      </geometry>
    </collision>
  </link>
  <gazebo reference="p3at_back_right_hub">
    <material value="Gazebo/Yellow"/>
  </gazebo>
  <joint name="p3at_back_right_hub_joint" type="fixed">
    <origin rpy="0 0 0" xyz="-0 -0.041 0"/>
    <parent link="p3at_back_right_axle"/>
    <child link="p3at_back_right_hub"/>
  </joint>
  <link name="p3at_back_right_wheel">
    <inertial>
      <mass value="0.5"/>
      <origin xyz="0 0 0"/>
      <inertia ixx="0.012411765597" ixy="0" ixz="0" iyy="0.015218160428" iyz="0" izz="0.011763977943"/>
    </inertial>
    <visual>
      <origin rpy="0 0 0" xyz="0 0 0"/>
      <geometry name="pioneer_geom">
        <mesh filename="package://athos_description/meshes/wheel.stl"/>
      </geometry>
      <material name="WheelBlack"/>
    </visual>
    <collision>
      <origin rpy="-1.57079635 0 0" xyz="0 0 0"/>
      <geometry>
        <!--mesh filename="package://athos_description/meshes/wheel.stl"/-->
        <cylinder length="0.075" radius="0.111"/>
      </geometry>
    </collision>
  </link>
  <gazebo reference="p3at_back_right_wheel">
    <material value="Gazebo/Black"/>
  </gazebo>
  <joint name="p3at_back_right_wheel_joint" type="continuous">
    <axis xyz="0 1 0"/>
    <anchor xyz="0 0 0"/>
    <limit effort="100" velocity="100"/>
    <joint_properties damping="0.7"/>
    <origin rpy="0 0 0" xyz="0 0 0"/>
    <parent link="p3at_back_right_hub"/>
    <child link="p3at_back_right_wheel"/>
  </joint>
  <gazebo reference="p3at_back_right_wheel">
    <kp>1000000.0</kp>
    <!-- kp and kd for rubber -->
    <kd>100.0</kd>
    <mu1>10.0</mu1>
    <mu2>1.0</mu2>
    <fdir1>0 1 0</fdir1>
    <!-- is this correct? -->
    <maxVel>1.0</maxVel>
    <minDepth>0.00</minDepth>
  </gazebo>
  <gazebo reference="p3at_front_right_wheel">
    <kp>1000000.0</kp>
    <!-- kp and kd for rubber -->
    <kd>100.0</kd>
    <mu1>10.0</mu1>
    <mu2>1.0</mu2>
    <fdir1>0 1 0</fdir1>
    <!-- is this correct? -->
    <maxVel>1.0</maxVel>
    <minDepth>0.00</minDepth>
  </gazebo>
  <!-- <joint name="pioneer2cyton" type="fixed">
	<origin xyz="0.08 0.071 0.004" rpy="0 0 0"/>
		<parent link="top_plate"/>
		<child link="link0"/>
</joint> -->
  <joint name="pioneer2suporte" type="fixed">
    <origin rpy="0 0 -1.57" xyz="0.073 0.160 0.004"/>
    <parent link="top_plate"/>
    <child link="suporte_base"/>
  </joint>
  <kinect_camera_v0 name="kinect" parent="suporte_kinect">
    <origin rpy="0 -3.9246 1.57" xyz="0.170 0.067 -0.035"/>
  </kinect_camera_v0>
  <gazebo>
    <plugin filename="libgazebo_ros_skid_steer_drive.so" name="skid_steer_drive_controller">
      <updateRate>100.0</updateRate>
      <!-- <robotNamespace>/</robotNamespace> -->
      <leftFrontJoint>p3at_front_left_wheel_joint</leftFrontJoint>
      <rightFrontJoint>p3at_front_right_wheel_joint</rightFrontJoint>
      <leftRearJoint>p3at_back_left_wheel_joint</leftRearJoint>
      <rightRearJoint>p3at_back_right_wheel_joint</rightRearJoint>
      <odometryTopic>pose</odometryTopic>
      <wheelSeparation>0.4</wheelSeparation>
      <wheelDiameter>0.215</wheelDiameter>
      <robotBaseFrame>base_link</robotBaseFrame>
      <commandTopic>cmd_vel</commandTopic>
      <odometryFrame>odom</odometryFrame>
      <broadcastTF>1</broadcastTF>
      <torque>200</torque>
      <topicName>cmd_vel</topicName>
    </plugin>
  </gazebo>
</robot>

